Workbook
Name column: [1]Sheet10!$A$1:$J$1
Name my_column: [1]Sheet9!$A$1:$J$1
Name my_table: [1]Sheet9!$A$1:$J$51
Name my_table1: [1]Sheet10!$A$1:$J$51
Name Slicer_Department: #N/A

Sheet Dashboard
D1: EMPLOYEE SALARY DASHBOARD
C5: =GETPIVOTDATA("Salary",Data!$M$27) -> 2981000 | E5: =GETPIVOTDATA("Average of Salary2",Data!$M$27) -> 59620 | G5: =GETPIVOTDATA("Department",Data!$M$40) -> 13 | I5: =GETPIVOTDATA("Salary",Data!$W$13) -> 357000 | K5: =GETPIVOTDATA("Score",Data!$M$4) -> 4215
C7: SUM OF Salary | E7: AVG SALARY | G7: ISACTIVE(TRUE) | I7: TOP 5 SALARY | K7: SUM OF SCORE

Sheet Data
A1: ID | B1: Name | C1: Age | D1: Email | E1: JoinDate | F1: Salary | G1: Department | H1: IsActive | I1: LastLogin | J1: Score | K1: Year
A2: 1 | B2: John Doe | C2: 29 | D2: john.doe@example.com | E2: 44576 | F2: 55000 | G2: Marketing | H2: TRUE | I2: 45536 | J2: 88 | K2: =YEAR(E2) -> 2022
A3: 2 | B3: Jane Smith | C3: 34 | D3: jane.smith@example.com | E3: 44523 | F3: 62000 | G3: Finance | H3: FALSE | I3: 45538 | J3: 92 | K3: =YEAR(E3) -> 2021
A4: 3 | B4: Bob Johnson | C4: 45 | D4: bob.johnson@example.com | E4: 43961 | F4: 75000 | G4: Engineering | H4: TRUE | I4: 45537 | J4: 77 | K4: =YEAR(E4) -> 2020 | M4: Row Labels | N4: Sum of Score
A5: 4 | B5: Alice Williams | C5: 28 | D5: alice.williams@example.com | E5: 45137 | F5: 47000 | G5: HR | H5: TRUE | I5: 45534 | J5: 85 | K5: =YEAR(E5) -> 2023 | M5: Engineering | N5: 889
A6: 5 | B6: Michael Brown | C6: 38 | D6: michael.brown@example.com | E6: 43699 | F6: 68000 | G6: Finance | H6: TRUE | I6: 45536 | J6: 90 | K6: =YEAR(E6) -> 2019 | M6: Finance | N6: 1137
A7: 6 | B7: Emily Davis | C7: 25 | D7: emily.davis@example.com | E7: 44635 | F7: 52000 | G7: Marketing | H7: TRUE | I7: 45529 | J7: 79 | K7: =YEAR(E7) -> 2022 | M7: HR | N7: 1124
A8: 7 | B8: David Wilson | C8: 31 | D8: david.wilson@example.com | E8: 44206 | F8: 60000 | G8: Engineering | H8: FALSE | I8: 45532 | J8: 83 | K8: =YEAR(E8) -> 2021 | M8: Marketing | N8: 1065
A9: 8 | B9: Sarah Moore | C9: 29 | D9: sarah.moore@example.com | E9: 44717 | F9: 55000 | G9: HR | H9: TRUE | I9: 45540 | J9: 91 | K9: =YEAR(E9) -> 2022 | M9: Grand Total | N9: 4215
A10: 9 | B10: James Taylor | C10: 40 | D10: james.taylor@example.com | E10: 43449 | F10: 70000 | G10: Marketing | H10: FALSE | I10: 45537 | J10: 70 | K10: =YEAR(E10) -> 2018
A11: 10 | B11: Lisa Anderson | C11: 36 | D11: lisa.anderson@example.com | E11: 44104 | F11: 65000 | G11: Finance | H11: TRUE | I11: 45538 | J11: 86 | K11: =YEAR(E11) -> 2020 | W11: Salary | X11: (All)
A12: 11 | B12: Chris Martinez | C12: 27 | D12: chris.martinez@example.com | E12: 44946 | F12: 48000 | G12: HR | H12: TRUE | I12: 45536 | J12: 93 | K12: =YEAR(E12) -> 2023
A13: 12 | B13: Karen Thomas | C13: 33 | D13: karen.thomas@example.com | E13: 44760 | F13: 62000 | G13: Engineering | H13: FALSE | I13: 45531 | J13: 80 | K13: =YEAR(E13) -> 2022 | W13: Row Labels | X13: Sum of Salary
A14: 13 | B14: Steven Jackson | C14: 40 | D14: steven.jackson@example.com | E14: 43824 | F14: 70000 | G14: Finance | H14: TRUE | I14: 45539 | J14: 87 | K14: =YEAR(E14) -> 2019 | W14: Bob Johnson | X14: 75000
A15: 14 | B15: Olivia Lee | C15: 30 | D15: olivia.lee@example.com | E15: 44484 | F15: 57000 | G15: Marketing | H15: TRUE | I15: 45536 | J15: 78 | K15: =YEAR(E15) -> 2021 | W15: George Baker | X15: 70000
A16: 15 | B16: Daniel Harris | C16: 35 | D16: daniel.harris@example.com | E16: 43913 | F16: 65000 | G16: HR | H16: FALSE | I16: 45534 | J16: 82 | K16: =YEAR(E16) -> 2020 | W16: James Taylor | X16: 70000
A17: 16 | B17: Megan Clark | C17: 26 | D17: megan.clark@example.com | E17: 45065 | F17: 49000 | G17: Marketing | H17: TRUE | I17: 45532 | J17: 84 | K17: =YEAR(E17) -> 2023 | W17: Samuel Perez | X17: 72000
A18: 17 | B18: Andrew Lewis | C18: 37 | D18: andrew.lewis@example.com | E18: 43353 | F18: 68000 | G18: Engineering | H18: TRUE | I18: 45537 | J18: 76 | K18: =YEAR(E18) -> 2018 | W18: Steven Jackson | X18: 70000
A19: 18 | B19: Laura Robinson | C19: 32 | D19: laura.robinson@example.com | E19: 44291 | F19: 61000 | G19: Finance | H19: FALSE | I19: 45538 | J19: 89 | K19: =YEAR(E19) -> 2021 | W19: Grand Total | X19: 357000
A20: 19 | B20: Paul Walker | C20: 29 | D20: paul.walker@example.com | E20: 44968 | F20: 53000 | G20: HR | H20: TRUE | I20: 45540 | J20: 92 | K20: =YEAR(E20) -> 2023
A21: 20 | B21: Nicole Young | C21: 31 | D21: nicole.young@example.com | E21: 44834 | F21: 59000 | G21: Marketing | H21: FALSE | I21: 45533 | J21: 81 | K21: =YEAR(E21) -> 2022
A22: 21 | B22: Mark Scott | C22: 28 | D22: mark.scott@example.com | E22: 44359 | F22: 55000 | G22: Engineering | H22: TRUE | I22: 45536 | J22: 80 | K22: =YEAR(E22) -> 2021
A23: 22 | B23: Jessica Hall | C23: 26 | D23: jessica.hall@example.com | E23: 44704 | F23: 51000 | G23: HR | H23: TRUE | I23: 45539 | J23: 88 | K23: =YEAR(E23) -> 2022
A24: 23 | B24: Kevin Allen | C24: 35 | D24: kevin.allen@example.com | E24: 43787 | F24: 67000 | G24: Finance | H24: TRUE | I24: 45537 | J24: 85 | K24: =YEAR(E24) -> 2019
A25: 24 | B25: Susan King | C25: 41 | D25: susan.king@example.com | E25: 43881 | F25: 69000 | G25: Marketing | H25: FALSE | I25: 45535 | J25: 77 | K25: =YEAR(E25) -> 2020 | M25: IsActive | N25: (All)
A26: 25 | B26: Jason Wright | C26: 29 | D26: jason.wright@example.com | E26: 44997 | F26: 54000 | G26: HR | H26: TRUE | I26: 45538 | J26: 82 | K26: =YEAR(E26) -> 2023
A27: 26 | B27: Emily Hill | C27: 34 | D27: emily.hill@example.com | E27: 44435 | F27: 61000 | G27: Engineering | H27: FALSE | I27: 45536 | J27: 79 | K27: =YEAR(E27) -> 2021 | M27: Sum of Salary | N27: Average of Salary2 | O27: Count of IsActive
A28: 27 | B28: Tyler Adams | C28: 28 | D28: tyler.adams@example.com | E28: 44665 | F28: 50000 | G28: Finance | H28: TRUE | I28: 45534 | J28: 84 | K28: =YEAR(E28) -> 2022 | M28: 2981000 | N28: 59620 | O28: 50
A29: 28 | B29: Grace Nelson | C29: 37 | D29: grace.nelson@example.com | E29: 43739 | F29: 68000 | G29: Marketing | H29: TRUE | I29: 45540 | J29: 86 | K29: =YEAR(E29) -> 2019
A30: 29 | B30: Brandon Carter | C30: 32 | D30: brandon.carter@example.com | E30: 43997 | F30: 63000 | G30: HR | H30: TRUE | I30: 45537 | J30: 90 | K30: =YEAR(E30) -> 2020
A31: 30 | B31: Rebecca Mitchell | C31: 29 | D31: rebecca.mitchell@example.com | E31: 45058 | F31: 56000 | G31: Engineering | H31: TRUE | I31: 45533 | J31: 78 | K31: =YEAR(E31) -> 2023
A32: 31 | B32: Samuel Perez | C32: 38 | D32: samuel.perez@example.com | E32: 43653 | F32: 72000 | G32: Finance | H32: TRUE | I32: 45536 | J32: 87 | K32: =YEAR(E32) -> 2019
A33: 32 | B33: Victoria Roberts | C33: 31 | D33: victoria.roberts@example.com | E33: 44252 | F33: 58000 | G33: Marketing | H33: FALSE | I33: 45532 | J33: 82 | K33: =YEAR(E33) -> 2021 | U33: Row Labels | V33: Count of IsActive
A34: 33 | B34: Anthony Morris | C34: 27 | D34: anthony.morris@example.com | E34: 45139 | F34: 52000 | G34: HR | H34: TRUE | I34: 45539 | J34: 83 | K34: =YEAR(E34) -> 2023 | U34: Engineering | V34: 11
A35: 34 | B35: Melissa Collins | C35: 35 | D35: melissa.collins@example.com | E35: 44183 | F35: 67000 | G35: Engineering | H35: TRUE | I35: 45538 | J35: 88 | K35: =YEAR(E35) -> 2020 | U35: Finance | V35: 13
A36: 35 | B36: George Baker | C36: 40 | D36: george.baker@example.com | E36: 43728 | F36: 70000 | G36: Finance | H36: FALSE | I36: 45536 | J36: 85 | K36: =YEAR(E36) -> 2019 | U36: HR | V36: 13
A37: 36 | B37: Amanda Allen | C37: 26 | D37: amanda.allen@example.com | E37: 44839 | F37: 49000 | G37: Marketing | H37: TRUE | I37: 45534 | J37: 79 | K37: =YEAR(E37) -> 2022 | U37: Marketing | V37: 13
A38: 37 | B38: Robert Johnson | C38: 33 | D38: robert.johnson@example.com | E38: 44270 | F38: 62000 | G38: HR | H38: FALSE | I38: 45537 | J38: 82 | K38: =YEAR(E38) -> 2021 | M38: IsActive | N38: (All) | U38: Grand Total | V38: 50
A39: 38 | B39: Nancy Turner | C39: 29 | D39: nancy.turner@example.com | E39: 44931 | F39: 53000 | G39: Engineering | H39: TRUE | I39: 45536 | J39: 90 | K39: =YEAR(E39) -> 2023
A40: 39 | B40: Steven Adams | C40: 31 | D40: steven.adams@example.com | E40: 44722 | F40: 60000 | G40: Finance | H40: TRUE | I40: 45531 | J40: 87 | K40: =YEAR(E40) -> 2022 | M40: Row Labels | N40: Count of Department
...
